Workbook

Sheet Lcode_mapping
A1: 1 | B1: 2 | C1: 3 | D1: 4 | E1: 5 | F1: 6 | G1: 7 | H1: 8 | I1: 9 | J1: 10 | K1: 11 | L1: 12 | M1: 13 | N1: 14 | O1: 15 | P1: 16 | Q1: 17 | R1: 18 | S1: 19 | T1: 20 | U1: 21 | V1: 22 | W1: 23 | X1: 24 | Y1: 25 | Z1: 26
A2: # | B2: L | C2: openDBVar | D2: Name | E2: D1 | F2: D2 | G2: D3 | H2: T | I2: A | J2: Descriptor | K2: Scope | L2: Comment | M2: RIKSN | N2: Wrapper | O2: Dir | P2: File | Q2: Include Calc | R2: NameOver | S2: NameVec | T2: Descriptor_override | U2: Time_Dim | V2: Original Units | W2: Tolerance | X2: FirstDB | Y2: LastDB | AA2: Description.
A3: 293 | B3: 2 | C3: =IF(R3="-",D3,R3) -> DummyName | D3: EFF FREQ | E3: 3 | F3: 1 | G3: 1 | H3: R | I3: 4 | J3: Effective freqs opposite band | K3: Obs | L3: - | M3: K | N3: - | O3: - | P3: - | Q3: - | R3: DummyName | S3: - | T3: NOTE: Split into 3 variables. | U3: - | V3: MHz | W3: - | X3: =VLOOKUP($D3,global_toc!$C:$K,7,FALSE) -> 79AUG03XX | Y3: =VLOOKUP($D3,global_toc!$C:$K,8,FALSE) -> 11OCT17XA | Z3: =VLOOKUP($D3,global_toc!$C:$K,9,FALSE) -> 3180 | AA3: =IF(T3="-",J3,T3) -> NOTE: Split into 3 variables.
A4: 492 | B4: 2 | C4: =IF(R4="-",D4,R4) -> UNCALDLY | D4: UNCALDLY | E4: 1 | F4: 1 | G4: 1 | H4: R | I4: 1 | J4: Phase cal delay (sec) | K4: Obs | L4: NEED THIS | M4: K | N4: - | O4: - | P4: - | Q4: - | R4: - | S4: - | T4: Bad Phase Cal Delay. Removed from Obs. | U4: - | V4: - | W4: - | X4: =VLOOKUP($D4,global_toc!$C:$K,7,FALSE) -> 83JUN06X_ | Y4: =VLOOKUP($D4,global_toc!$C:$K,8,FALSE) -> 84OCT31X_ | Z4: =VLOOKUP($D4,global_toc!$C:$K,9,FALSE) -> 11 | AA4: =IF(T4="-",J4,T4) -> Bad Phase Cal Delay. Removed from Obs.
A5: 118 | B5: 1 | C5: =IF(R5="-",D5,R5) -> CLK_CFLG | D5: CLK_CFLG | E5: 1 | F5: 1 | G5: 1 | H5: A | I5: 4 | J5: Clock constraint use flag. | K5: Session | L5: Part of (CLK_CFLG, CC_SITS,CLK_CNST) | M5: S | N5: - | O5: - | P5: - | Q5: - | R5: - | S5: - | T5: - | U5: - | V5: - | W5: - | X5: =VLOOKUP($D5,global_toc!$C:$K,7,FALSE) -> 79AUG03XX | Y5: =VLOOKUP($D5,global_toc!$C:$K,8,FALSE) -> 11OCT17XA | Z5: =VLOOKUP($D5,global_toc!$C:$K,9,FALSE) -> 5029 | AA5: =IF(T5="-",J5,T5) -> Clock constraint use flag.
A6: 119 | B6: 1 | C6: =IF(R6="-",D6,R6) -> EXPNAME | D6: EXPNAME | E6: 16 | F6: 1 | G6: 1 | H6: A | I6: 3 | J6: Observing program (exp.) name | K6: Session | L6: - | M6: S | N6: - | O6: - | P6: - | Q6: - | R6: - | S6: - | T6: - | U6: - | V6: - | W6: - | X6: =VLOOKUP($D6,global_toc!$C:$K,7,FALSE) -> 99OCT18XA | Y6: =VLOOKUP($D6,global_toc!$C:$K,8,FALSE) -> 00OCT17XE | Z6: =VLOOKUP($D6,global_toc!$C:$K,9,FALSE) -> 51 | AA6: =IF(T6="-",J6,T6) -> Observing program (exp.) name
A7: 122 | B7: 1 | C7: =IF(R7="-",D7,R7) -> Correlator | D7: CORPLACE | E7: 16 | F7: 1 | G7: 1 | H7: A | I7: 1 | J7: Correlator name. | K7: Session | L7: - | M7: K | N7: NGS | O7: - | P7: Head | Q7: - | R7: Correlator | S7: - | T7: - | U7: - | V7: - | W7: - | X7: =VLOOKUP($D7,global_toc!$C:$K,7,FALSE) -> 97DEC03XN | Y7: =VLOOKUP($D7,global_toc!$C:$K,8,FALSE) -> 11OCT17XA | Z7: =VLOOKUP($D7,global_toc!$C:$K,9,FALSE) -> 1701 | AA7: =IF(T7="-",J7,T7) -> Correlator name.
A8: 123 | B8: 1 | C8: =IF(R8="-",D8,R8) -> CorrelatorType | D8: CORRTYPE | E8: 4 | F8: 1 | G8: 1 | H8: A | I8: 1 | J8: Correlator type: MK3/MK4/K4 etc. | K8: Session | L8: - | M8: K | N8: NGS | O8: - | P8: Head | Q8: - | R8: CorrelatorType | S8: - | T8: - | U8: - | V8: - | W8: - | X8: =VLOOKUP($D8,global_toc!$C:$K,7,FALSE) -> 94JUL08XV | Y8: =VLOOKUP($D8,global_toc!$C:$K,8,FALSE) -> 11OCT17XA | Z8: =VLOOKUP($D8,global_toc!$C:$K,9,FALSE) -> 1784 | AA8: =IF(T8="-",J8,T8) -> Correlator type: MK3/MK4/K4 etc.
A9: 125 | B9: 1 | C9: =IF(R9="-",D9,R9) -> ExpDescription | D9: EXPDESC | E9: 40 | F9: 1 | G9: 1 | H9: A | I9: 1 | J9: Experiment description. | K9: Session | L9: - | M9: K | N9: NGS | O9: - | P9: Head | Q9: - | R9: ExpDescription | S9: - | T9: - | U9: - | V9: - | W9: - | X9: =VLOOKUP($D9,global_toc!$C:$K,7,FALSE) -> 97DEC03XN | Y9: =VLOOKUP($D9,global_toc!$C:$K,8,FALSE) -> 11OCT17XA | Z9: =VLOOKUP($D9,global_toc!$C:$K,9,FALSE) -> 1651 | AA9: =IF(T9="-",J9,T9) -> Experiment description.
A10: 124 | B10: 1 | C10: =IF(R10="-",D10,R10) -> ExpName | D10: EXPCODE | E10: 16 | F10: 1 | G10: 1 | H10: A | I10: 1 | J10: Experiment name. | K10: Session | L10: - | M10: K | N10: NGS | O10: - | P10: Head | Q10: - | R10: ExpName | S10: - | T10: - | U10: - | V10: - | W10: - | X10: =VLOOKUP($D10,global_toc!$C:$K,7,FALSE) -> 97DEC03XN | Y10: =VLOOKUP($D10,global_toc!$C:$K,8,FALSE) -> 11OCT17XA | Z10: =VLOOKUP($D10,global_toc!$C:$K,9,FALSE) -> 1651 | AA10: =IF(T10="-",J10,T10) -> Experiment name.
A11: 126 | B11: 1 | C11: =IF(R11="-",D11,R11) -> ExpSerialNumber | D11: EXPSERNO | E11: 1 | F11: 1 | G11: 1 | H11: I | I11: 1 | J11: Experiment Serial Number. | K11: Session | L11: - | M11: K | N11: NGS | O11: - | P11: Head | Q11: - | R11: ExpSerialNumber | S11: - | T11: - | U11: - | V11: - | W11: - | X11: =VLOOKUP($D11,global_toc!$C:$K,7,FALSE) -> 94JUL08XV | Y11: =VLOOKUP($D11,global_toc!$C:$K,8,FALSE) -> 11OCT17XA | Z11: =VLOOKUP($D11,global_toc!$C:$K,9,FALSE) -> 1734 | AA11: =IF(T11="-",J11,T11) -> Experiment Serial Number.
A12: 128 | B12: 1 | C12: =IF(R12="-",D12,R12) -> iUTCInterval | D12: INTRVAL4 | E12: 5 | F12: 2 | G12: 1 | H12: I | I12: 1 | J12: First last UTC tag 4 digit year | K12: Session | L12: See also INTERVAL | M12: K | N12: NGS | O12: - | P12: Head | Q12: - | R12: iUTCInterval | S12: - | T12: First and last UTC time tag in input file. | U12: - | V12: - | W12: - | X12: =VLOOKUP($D12,global_toc!$C:$K,7,FALSE) -> 89FEB22DX | Y12: =VLOOKUP($D12,global_toc!$C:$K,8,FALSE) -> 11OCT17XA | Z12: =VLOOKUP($D12,global_toc!$C:$K,9,FALSE) -> 1915 | AA12: =IF(T12="-",J12,T12) -> First and last UTC time tag in input file.
A13: 127 | B13: 1 | C13: =IF(R13="-",D13,R13) -> iUTCInterval | D13: INTERVAL | E13: 5 | F13: 2 | G13: 1 | H13: I | I13: 1 | J13: First last UTC tag in input file | K13: Session | L13: - | M13: K | N13: NGS | O13: - | P13: Head | Q13: - | R13: iUTCInterval | S13: - | T13: First and last UTC time tag in input file. | U13: - | V13: - | W13: - | X13: =VLOOKUP($D13,global_toc!$C:$K,7,FALSE) -> 79AUG03XX | Y13: =VLOOKUP($D13,global_toc!$C:$K,8,FALSE) -> 11OCT17XA | Z13: =VLOOKUP($D13,global_toc!$C:$K,9,FALSE) -> 5029 | AA13: =IF(T13="-",J13,T13) -> First and last UTC time tag in input file.
A14: 130 | B14: 1 | C14: =IF(R14="-",D14,R14) -> NumObs | D14: NUMB OBS | E14: 1 | F14: 1 | G14: 1 | H14: I | I14: 4 | J14: Number of observations in file. | K14: Session | L14: - | M14: S | N14: NGS | O14: - | P14: Head | Q14: - | R14: NumObs | S14: - | T14: - | U14: - | V14: - | W14: - | X14: =VLOOKUP($D14,global_toc!$C:$K,7,FALSE) -> 79AUG03XX | Y14: =VLOOKUP($D14,global_toc!$C:$K,8,FALSE) -> 11OCT17XA | Z14: =VLOOKUP($D14,global_toc!$C:$K,9,FALSE) -> 5029 | AA14: =IF(T14="-",J14,T14) -> Number of observations in file.
A15: 129 | B15: 1 | C15: =IF(R15="-",D15,R15) -> NumObs | D15: NUM4 OBS | E15: 1 | F15: 1 | G15: 1 | H15: J | I15: 4 | J15: Number of observations (I*4) | K15: Session | L15: Either NUM4 OBS or NUMB OBS is required | M15: S | N15: NGS | O15: - | P15: Head | Q15: - | R15: NumObs | S15: - | T15: - | U15: - | V15: - | W15: - | X15: =VLOOKUP($D15,global_toc!$C:$K,7,FALSE) -> 79AUG03XX | Y15: =VLOOKUP($D15,global_toc!$C:$K,8,FALSE) -> 11OCT17XA | Z15: =VLOOKUP($D15,global_toc!$C:$K,9,FALSE) -> 2598 | AA15: =IF(T15="-",J15,T15) -> Number of observations (I*4)
A16: 131 | B16: N | C16: =IF(R16="-",D16,R16) -> NumScan | D16: NumScan | E16: 1 | F16: 1 | G16: 1 | H16: J | I16: 1 | J16: Number of Scans (Integer*4) | K16: Session | L16: - | M16: S | N16: NGS | O16: - | P16: Head | Q16: - | R16: NumScan | S16: - | T16: - | U16: - | V16: - | W16: - | X16: =VLOOKUP($D16,global_toc!$C:$K,7,FALSE) -> #N/A | Y16: =VLOOKUP($D16,global_toc!$C:$K,8,FALSE) -> #N/A | Z16: =VLOOKUP($D16,global_toc!$C:$K,9,FALSE) -> #N/A | AA16: =IF(T16="-",J16,T16) -> Number of Scans (Integer*4)
A17: 121 | B17: 1 | C17: =IF(R17="-",D17,R17) -> NumSource | D17: # STARS | E17: 1 | F17: 1 | G17: 1 | H17: I | I17: 1 | J17: Number of radio sources. | K17: Session | L17: - | M17: R | N17: NGS | O17: - | P17: Head | Q17: - | R17: NumSource | S17: - | T17: - | U17: - | V17: - | W17: - | X17: =VLOOKUP($D17,global_toc!$C:$K,7,FALSE) -> 79AUG03XX | Y17: =VLOOKUP($D17,global_toc!$C:$K,8,FALSE) -> 11OCT17XA | Z17: =VLOOKUP($D17,global_toc!$C:$K,9,FALSE) -> 5029 | AA17: =IF(T17="-",J17,T17) -> Number of radio sources.
A18: 120 | B18: 1 | C18: =IF(R18="-",D18,R18) -> NumStation | D18: # SITES | E18: 1 | F18: 1 | G18: 1 | H18: I | I18: 1 | J18: Number of sites. | K18: Session | L18: - | M18: R | N18: NGS | O18: - | P18: Head | Q18: - | R18: NumStation | S18: - | T18: - | U18: - | V18: - | W18: - | X18: =VLOOKUP($D18,global_toc!$C:$K,7,FALSE) -> 79AUG03XX | Y18: =VLOOKUP($D18,global_toc!$C:$K,8,FALSE) -> 11OCT17XA | Z18: =VLOOKUP($D18,global_toc!$C:$K,9,FALSE) -> 5029 | AA18: =IF(T18="-",J18,T18) -> Number of sites.
A19: 132 | B19: 1 | C19: =IF(R19="-",D19,R19) -> PrincipalInvestigator | D19: PI NAME | E19: 40 | F19: 1 | G19: 1 | H19: A | I19: 1 | J19: Agency/contact_person/PI name. | K19: Session | L19: - | M19: K | N19: NGS | O19: - | P19: Head | Q19: - | R19: PrincipalInvestigator | S19: - | T19: - | U19: - | V19: - | W19: - | X19: =VLOOKUP($D19,global_toc!$C:$K,7,FALSE) -> 97DEC03XN | Y19: =VLOOKUP($D19,global_toc!$C:$K,8,FALSE) -> 11OCT17XA | Z19: =VLOOKUP($D19,global_toc!$C:$K,9,FALSE) -> 1651 | AA19: =IF(T19="-",J19,T19) -> Agency/contact_person/PI name.
A20: 133 | B20: 1 | C20: =IF(R20="-",D20,R20) -> RecordingMode | D20: RECMODE | E20: 40 | F20: 1 | G20: 1 | H20: A | I20: 1 | J20: Recoding mode. | K20: Session | L20: - | M20: K | N20: Solve | O20: - | P20: Head | Q20: - | R20: RecordingMode | S20: - | T20: - | U20: - | V20: - | W20: - | X20: =VLOOKUP($D20,global_toc!$C:$K,7,FALSE) -> 94JUL08XV | Y20: =VLOOKUP($D20,global_toc!$C:$K,8,FALSE) -> 11OCT17XA | Z20: =VLOOKUP($D20,global_toc!$C:$K,9,FALSE) -> 1734 | AA20: =IF(T20="-",J20,T20) -> Recoding mode.
A21: 135 | B21: N | C21: =IF(R21="-",D21,R21) -> SourceList | D21: SourceList | E21: 4 | F21: 70 | G21: 1 | H21: A | I21: 1 | J21: Source names array. | K21: Session | L21: - | M21: K | N21: NGS | O21: - | P21: Head | Q21: - | R21: SourceList | S21: - | T21: - | U21: - | V21: - | W21: - | X21: =VLOOKUP($D21,global_toc!$C:$K,7,FALSE) -> #N/A | Y21: =VLOOKUP($D21,global_toc!$C:$K,8,FALSE) -> #N/A | Z21: =VLOOKUP($D21,global_toc!$C:$K,9,FALSE) -> #N/A | AA21: =IF(T21="-",J21,T21) -> Source names array.
A22: 134 | B22: N | C22: =IF(R22="-",D22,R22) -> StationList | D22: StationList | E22: 4 | F22: 11 | G22: 1 | H22: A | I22: 1 | J22: Site names array. | K22: Session | L22: - | M22: K | N22: NGS | O22: - | P22: Head | Q22: - | R22: StationList | S22: - | T22: - | U22: - | V22: - | W22: - | X22: =VLOOKUP($D22,global_toc!$C:$K,7,FALSE) -> #N/A | Y22: =VLOOKUP($D22,global_toc!$C:$K,8,FALSE) -> #N/A | Z22: =VLOOKUP($D22,global_toc!$C:$K,9,FALSE) -> #N/A | AA22: =IF(T22="-",J22,T22) -> Site names array.
A23: 266 | B23: 2 | C23: =IF(R23="-",D23,R23) -> AzTheo | D23: AZ-THEO | E23: 2 | F23: 2 | G23: 1 | H23: R | I23: 5 | J23: Azimuth array definition | K23: Station | L23: - | M23: K | N23: NGS | O23: - | P23: AzEl | Q23: - | R23: AzTheo | S23: - | T23: - | U23: 2 | V23: radian | W23: 1.d-8 2.d-11 | X23: =VLOOKUP($D23,global_toc!$C:$K,7,FALSE) -> 79AUG03XX | Y23: =VLOOKUP($D23,global_toc!$C:$K,8,FALSE) -> 11OCT17XA | Z23: =VLOOKUP($D23,global_toc!$C:$K,9,FALSE) -> 5029 | AA23: =IF(T23="-",J23,T23) -> Azimuth array definition
A24: 267 | B24: 2 | C24: =IF(R24="-",D24,R24) -> ElTheo | D24: EL-THEO | E24: 2 | F24: 2 | G24: 1 | H24: R | I24: 5 | J24: Elevation array definition | K24: Station | L24: - | M24: K | N24: NGS | O24: - | P24: AzEl | Q24: - | R24: ElTheo | S24: - | T24: - | U24: 2 | V24: radian | W24: 1.d-8 2.d-11 | X24: =VLOOKUP($D24,global_toc!$C:$K,7,FALSE) -> 79AUG03XX | Y24: =VLOOKUP($D24,global_toc!$C:$K,8,FALSE) -> 11OCT17XA | Z24: =VLOOKUP($D24,global_toc!$C:$K,9,FALSE) -> 5029 | AA24: =IF(T24="-",J24,T24) -> Elevation array definition
A25: 268 | B25: 2 | C25: =IF(R25="-",D25,R25) -> Cal-AxisOffset | D25: AXO CONT | E25: 2 | F25: 2 | G25: 1 | H25: R | I25: 5 | J25: New Axis Offset Contributions | K25: Station | L25: - | M25: K | N25: Solve | O25: - | P25: Cal-AxisOffset | Q25: Y | R25: Cal-AxisOffset | S25: - | T25: - | U25: 2 | V25: second | W25: 1.0d-13 2.d-18 Flip | X25: =VLOOKUP($D25,global_toc!$C:$K,7,FALSE) -> 79AUG03XX | Y25: =VLOOKUP($D25,global_toc!$C:$K,8,FALSE) -> 11OCT17XA | Z25: =VLOOKUP($D25,global_toc!$C:$K,9,FALSE) -> 5029 | AA25: =IF(T25="-",J25,T25) -> New Axis Offset Contributions
A26: 269 | B26: 2 | C26: =IF(R26="-",D26,R26) -> Cal-Cable | D26: CABL DEL | E26: 2 | F26: 2 | G26: 1 | H26: R | I26: 3 | J26: Cable calibration data | K26: Station | L26: - | M26: K | N26: NGS | O26: - | P26: Cal-Cable | Q26: - | R26: Cal-Cable | S26: - | T26: - | U26: 1 | V26: second | W26: 1.d-15 2.d-18 | X26: =VLOOKUP($D26,global_toc!$C:$K,7,FALSE) -> 79AUG03XX | Y26: =VLOOKUP($D26,global_toc!$C:$K,8,FALSE) -> 11OCT17XA | Z26: =VLOOKUP($D26,global_toc!$C:$K,9,FALSE) -> 5002 | AA26: =IF(T26="-",J26,T26) -> Cable calibration data
A27: 271 | B27: N | C27: =IF(R27="-",D27,R27) -> Cal-CableDataFlag | D27: CableDataFlag | E27: 1 | F27: 1 | G27: 1 | H27: I | I27: 3 | J27: - | K27: Station | L27: - | M27: K | N27: NGS | O27: - | P27: Cal-Cable | Q27: - | R27: Cal-CableDataFlag | S27: - | T27: 0=OK, -1=Missing, -2=bad, 1=Used Near pt | U27: - | V27: - | W27: - | X27: =VLOOKUP($D27,global_toc!$C:$K,7,FALSE) -> #N/A | Y27: =VLOOKUP($D27,global_toc!$C:$K,8,FALSE) -> #N/A | Z27: =VLOOKUP($D27,global_toc!$C:$K,9,FALSE) -> #N/A | AA27: =IF(T27="-",J27,T27) -> 0=OK, -1=Missing, -2=bad, 1=Used Near pt
A28: 270 | B28: N | C28: =IF(R28="-",D28,R28) -> Cal-CableHistory | D28: CableCalHistory | E28: 30 | F28: 1 | G28: 1 | H28: A | I28: N | J28: Description of cable-cal processing | K28: Station | L28: - | M28: K | N28: Solve | O28: - | P28: Cal-Cable | Q28: - | R28: Cal-CableHistory | S28: - | T28: - | U28: - | V28: - | W28: - | X28: =VLOOKUP($D28,global_toc!$C:$K,7,FALSE) -> #N/A | Y28: =VLOOKUP($D28,global_toc!$C:$K,8,FALSE) -> #N/A | Z28: =VLOOKUP($D28,global_toc!$C:$K,9,FALSE) -> #N/A | AA28: =IF(T28="-",J28,T28) -> Description of cable-cal processing
A29: 272 | B29: 2 | C29: =IF(R29="-",D29,R29) -> Cal-SlantPathTropDry | D29: NDRYCONT | E29: 2 | F29: 2 | G29: 1 | H29: R | I29: 5 | J29: Nhmf (dry) atm. contribution | K29: Station | L29: - | M29: K | N29: Solve | O29: - | P29: Cal-SlantPathTropDry_kNMF | Q29: Y | R29: Cal-SlantPathTropDry | S29: - | T29: - | U29: 2 | V29: second | W29: 1.d-13 1.d-16 Flip | X29: =VLOOKUP($D29,global_toc!$C:$K,7,FALSE) -> 79AUG03XX | Y29: =VLOOKUP($D29,global_toc!$C:$K,8,FALSE) -> 11OCT17XA | Z29: =VLOOKUP($D29,global_toc!$C:$K,9,FALSE) -> 5029 | AA29: =IF(T29="-",J29,T29) -> Nhmf (dry) atm. contribution
A30: 273 | B30: 2 | C30: =IF(R30="-",D30,R30) -> Cal-SlantPathTropWet | D30: NWETCONT | E30: 2 | F30: 2 | G30: 1 | H30: R | I30: 5 | J30: Whmf (wet) atm. contribution | K30: Station | L30: - | M30: K | N30: Solve | O30: - | P30: Cal-SlantPathTropWet_kNMF | Q30: Y | R30: Cal-SlantPathTropWet | S30: - | T30: - | U30: 2 | V30: second | W30: 1.d-13 1.d-16 Flip | X30: =VLOOKUP($D30,global_toc!$C:$K,7,FALSE) -> 79AUG03XX | Y30: =VLOOKUP($D30,global_toc!$C:$K,8,FALSE) -> 11OCT17XA | Z30: =VLOOKUP($D30,global_toc!$C:$K,9,FALSE) -> 5029 | AA30: =IF(T30="-",J30,T30) -> Whmf (wet) atm. contribution
A31: 274 | B31: 2 | C31: =IF(R31="-",D31,R31) -> Cal-StationOceanLoadHoriz | D31: OCE HORZ | E31: 2 | F31: 2 | G31: 1 | H31: R | I31: 5 | J31: Site-dep ocean cont - horizontal | K31: Station | L31: - | M31: K | N31: - | O31: - | P31: Cal-StationOceanLoad | Q31: Y | R31: Cal-StationOceanLoadHoriz | S31: - | T31: - | U31: 2 | V31: second | W31: 1.d-6 1.d-9 | X31: =VLOOKUP($D31,global_toc!$C:$K,7,FALSE) -> 79AUG03XX | Y31: =VLOOKUP($D31,global_toc!$C:$K,8,FALSE) -> 11OCT17XA | Z31: =VLOOKUP($D31,global_toc!$C:$K,9,FALSE) -> 5029 | AA31: =IF(T31="-",J31,T31) -> Site-dep ocean cont - horizontal
A32: 275 | B32: 2 | C32: =IF(R32="-",D32,R32) -> Cal-StationOceanLoadVert | D32: OCE VERT | E32: 2 | F32: 2 | G32: 1 | H32: R | I32: 5 | J32: Site-dep ocean cont - vertical | K32: Station | L32: - | M32: K | N32: - | O32: - | P32: Cal-StationOceanLoad | Q32: Y | R32: Cal-StationOceanLoadVert | S32: - | T32: - | U32: 2 | V32: second | W32: 1.d-6 1.d-9 | X32: =VLOOKUP($D32,global_toc!$C:$K,7,FALSE) -> 79AUG03XX | Y32: =VLOOKUP($D32,global_toc!$C:$K,8,FALSE) -> 11OCT17XA | Z32: =VLOOKUP($D32,global_toc!$C:$K,9,FALSE) -> 5029 | AA32: =IF(T32="-",J32,T32) -> Site-dep ocean cont - vertical
A33: 276 | B33: 2 | C33: =IF(R33="-",D33,R33) -> Dis-OceanLoad | D33: OCE DELD | E33: 3 | F33: 2 | G33: 2 | H33: R | I33: 5 | J33: Ocean load site depndnt displace | K33: Station | L33: - | M33: K | N33: - | O33: - | P33: Dis-OceanLoad | Q33: Y | R33: Dis-OceanLoad | S33: - | T33: - | U33: 2 | V33: meter | W33: 1.d-6 1.d-9 | X33: =VLOOKUP($D33,global_toc!$C:$K,7,FALSE) -> 79AUG03XX | Y33: =VLOOKUP($D33,global_toc!$C:$K,8,FALSE) -> 11OCT17XA | Z33: =VLOOKUP($D33,global_toc!$C:$K,9,FALSE) -> 5029 | AA33: =IF(T33="-",J33,T33) -> Ocean load site depndnt displace
A34: 280 | B34: 2 | C34: =IF(R34="-",D34,R34) -> FeedRotation | D34: PARANGLE | E34: 2 | F34: 1 | G34: 1 | H34: R | I34: 5 | J34: Feedhorn rot. angle ref and rem | K34: Station | L34: - | M34: k | N34: - | O34: - | P34: FeedRotation | Q34: Y | R34: FeedRotation | S34: - | T34: Feedhorn rotation angle. | U34: 1 | V34: degree | W34: 1.d-6 | X34: =VLOOKUP($D34,global_toc!$C:$K,7,FALSE) -> 79AUG03XX | Y34: =VLOOKUP($D34,global_toc!$C:$K,8,FALSE) -> 11OCT17XA | Z34: =VLOOKUP($D34,global_toc!$C:$K,9,FALSE) -> 5029 | AA34: =IF(T34="-",J34,T34) -> Feedhorn rotation angle.
A35: 277 | B35: 2 | C35: =IF(R35="-",D35,R35) -> AtmPres | D35: ATM PRES | E35: 2 | F35: 2 | G35: 1 | H35: R | I35: 3 | J35: Pressure in mb at site | K35: Station | L35: - | M35: K | N35: NGS | O35: - | P35: Met | Q35: - | R35: AtmPres | S35: - | T35: Pressure in hPa at site | U35: 1 | V35: hPa | W35: 1.d-4 | X35: =VLOOKUP($D35,global_toc!$C:$K,7,FALSE) -> 79AUG03XX | Y35: =VLOOKUP($D35,global_toc!$C:$K,8,FALSE) -> 11OCT17XA | Z35: =VLOOKUP($D35,global_toc!$C:$K,9,FALSE) -> 5022 | AA35: =IF(T35="-",J35,T35) -> Pressure in hPa at site
A36: 278 | B36: 2 | C36: =IF(R36="-",D36,R36) -> RelHum | D36: REL.HUM. | E36: 2 | F36: 2 | G36: 1 | H36: R | I36: 3 | J36: Rel.Hum. at local WX st (50%=.5) | K36: Station | L36: - | M36: K | N36: NGS | O36: - | P36: Met | Q36: - | R36: RelHum | S36: - | T36: - | U36: 1 | V36: % | W36: 1.d-4 | X36: =VLOOKUP($D36,global_toc!$C:$K,7,FALSE) -> 79AUG03XX | Y36: =VLOOKUP($D36,global_toc!$C:$K,8,FALSE) -> 11OCT17XA | Z36: =VLOOKUP($D36,global_toc!$C:$K,9,FALSE) -> 5022 | AA36: =IF(T36="-",J36,T36) -> Rel.Hum. at local WX st (50%=.5)
A37: 279 | B37: 2 | C37: =IF(R37="-",D37,R37) -> TempC | D37: TEMP C | E37: 2 | F37: 2 | G37: 1 | H37: R | I37: 3 | J37: Temp in C at local WX station | K37: Station | L37: - | M37: K | N37: NGS | O37: - | P37: Met | Q37: - | R37: TempC | S37: - | T37: - | U37: 1 | V37: Celsius | W37: 1.d-4 | X37: =VLOOKUP($D37,global_toc!$C:$K,7,FALSE) -> 79AUG03XX | Y37: =VLOOKUP($D37,global_toc!$C:$K,8,FALSE) -> 11OCT17XA | Z37: =VLOOKUP($D37,global_toc!$C:$K,9,FALSE) -> 5022 | AA37: =IF(T37="-",J37,T37) -> Temp in C at local WX station
A38: 281 | B38: 2 | C38: =IF(R38="-",D38,R38) -> Part-AxisOffset | D38: AXO PART | E38: 2 | F38: 2 | G38: 1 | H38: R | I38: 5 | J38: Axis Offset partial deriv. def. | K38: Station | L38: - | M38: K | N38: Solve | O38: - | P38: Part-AxisOffset | Q38: Y | R38: Part-AxisOffset | S38: - | T38: - | U38: 2 | V38: second | W38: 1.d-14 2.d-18 Flip | X38: =VLOOKUP($D38,global_toc!$C:$K,7,FALSE) -> 79AUG03XX | Y38: =VLOOKUP($D38,global_toc!$C:$K,8,FALSE) -> 11OCT17XA | Z38: =VLOOKUP($D38,global_toc!$C:$K,9,FALSE) -> 5029 | AA38: =IF(T38="-",J38,T38) -> Axis Offset partial deriv. def.
A39: 294 | B39: 2 | C39: =IF(R39="-",D39,R39) -> Part-HorizonGrad | D39: NGRADPAR | E39: 2 | F39: 2 | G39: 2 | H39: R | I39: 5 | J39: Niell dry atm. gradient partials | K39: Station | L39: - | M39: S | N39: Solve | O39: - | P39: Part-HorizonGrad_kNMF | Q39: Y | R39: Part-HorizonGrad | S39: NMFGrad_EW NMFGrad_NS | T39: - | U39: 2 | V39: second | W39: 1.d-6 1.d-9 Flip | X39: =VLOOKUP($D39,global_toc!$C:$K,7,FALSE) -> 79AUG03XX | Y39: =VLOOKUP($D39,global_toc!$C:$K,8,FALSE) -> 11OCT17XA | Z39: =VLOOKUP($D39,global_toc!$C:$K,9,FALSE) -> 5029 | AA39: =IF(T39="-",J39,T39) -> Niell dry atm. gradient partials
A40: 282 | B40: 2 | C40: =IF(R40="-",D40,R40) -> Part-ZenithPathTropDry | D40: NDRYPART | E40: 2 | F40: 2 | G40: 1 | H40: R | I40: 5 | J40: Nhmf2 dry partial deriv. def. | K40: Station | L40: - | M40: K | N40: Solve | O40: - | P40: Part-ZenithPathTropDry_kNMF | Q40: Y | R40: Part-ZenithPathTropDry | S40: - | T40: - | U40: 2 | V40: second | W40: 1.d-6 1.d-9 Flip | X40: =VLOOKUP($D40,global_toc!$C:$K,7,FALSE) -> 79AUG03XX | Y40: =VLOOKUP($D40,global_toc!$C:$K,8,FALSE) -> 11OCT17XA | Z40: =VLOOKUP($D40,global_toc!$C:$K,9,FALSE) -> 5029 | AA40: =IF(T40="-",J40,T40) -> Nhmf2 dry partial deriv. def.
...

Sheet Lcode_mapping_new
A1: =Lcode_mapping!A1 -> 1 | B1: =Lcode_mapping!B1 -> 2 | C1: =Lcode_mapping!D1 -> 4 | D1: =Lcode_mapping!E1 -> 5 | E1: =Lcode_mapping!F1 -> 6 | F1: =Lcode_mapping!G1 -> 7 | G1: =Lcode_mapping!H1 -> 8 | H1: =Lcode_mapping!I1 -> 9 | I1: =Lcode_mapping!J1 -> 10 | J1: =Lcode_mapping!K1 -> 11 | ... V1: =Lcode_mapping!W1 -> 23
A2: =Lcode_mapping!A2 -> # | B2: =Lcode_mapping!B2 -> L | C2: =Lcode_mapping!D2 -> Name | D2: =Lcode_mapping!E2 -> D1 | E2: =Lcode_mapping!F2 -> D2 | F2: =Lcode_mapping!G2 -> D3 | G2: =Lcode_mapping!H2 -> T | H2: =Lcode_mapping!I2 -> A | I2: =Lcode_mapping!J2 -> Descriptor | J2: =Lcode_mapping!K2 -> Scope | ... V2: =Lcode_mapping!W2 -> Tolerance
A3: =Lcode_mapping!A3 -> 293 | B3: =Lcode_mapping!B3 -> 2 | C3: =Lcode_mapping!D3 -> EFF FREQ | D3: =Lcode_mapping!E3 -> 3 | E3: =Lcode_mapping!F3 -> 1 | F3: =Lcode_mapping!G3 -> 1 | G3: =Lcode_mapping!H3 -> R | H3: =Lcode_mapping!I3 -> 4 | I3: =Lcode_mapping!J3 -> Effective freqs opposite band | J3: =Lcode_mapping!K3 -> Obs | ... V3: =Lcode_mapping!W3 -> -
A4: =Lcode_mapping!A4 -> 492 | B4: =Lcode_mapping!B4 -> 2 | C4: =Lcode_mapping!D4 -> UNCALDLY | D4: =Lcode_mapping!E4 -> 1 | E4: =Lcode_mapping!F4 -> 1 | F4: =Lcode_mapping!G4 -> 1 | G4: =Lcode_mapping!H4 -> R | H4: =Lcode_mapping!I4 -> 1 | I4: =Lcode_mapping!J4 -> Phase cal delay (sec) | J4: =Lcode_mapping!K4 -> Obs | ... V4: =Lcode_mapping!W4 -> -
A5: =Lcode_mapping!A5 -> 118 | B5: =Lcode_mapping!B5 -> 1 | C5: =Lcode_mapping!D5 -> CLK_CFLG | D5: =Lcode_mapping!E5 -> 1 | E5: =Lcode_mapping!F5 -> 1 | F5: =Lcode_mapping!G5 -> 1 | G5: =Lcode_mapping!H5 -> A | H5: =Lcode_mapping!I5 -> 4 | I5: =Lcode_mapping!J5 -> Clock constraint use flag. | J5: =Lcode_mapping!K5 -> Session | ... V5: =Lcode_mapping!W5 -> -
A6: =Lcode_mapping!A6 -> 119 | B6: =Lcode_mapping!B6 -> 1 | C6: =Lcode_mapping!D6 -> EXPNAME | D6: =Lcode_mapping!E6 -> 16 | E6: =Lcode_mapping!F6 -> 1 | F6: =Lcode_mapping!G6 -> 1 | G6: =Lcode_mapping!H6 -> A | H6: =Lcode_mapping!I6 -> 3 | I6: =Lcode_mapping!J6 -> Observing program (exp.) name | J6: =Lcode_mapping!K6 -> Session | ... V6: =Lcode_mapping!W6 -> -
A7: =Lcode_mapping!A7 -> 122 | B7: =Lcode_mapping!B7 -> 1 | C7: =Lcode_mapping!D7 -> CORPLACE | D7: =Lcode_mapping!E7 -> 16 | E7: =Lcode_mapping!F7 -> 1 | F7: =Lcode_mapping!G7 -> 1 | G7: =Lcode_mapping!H7 -> A | H7: =Lcode_mapping!I7 -> 1 | I7: =Lcode_mapping!J7 -> Correlator name. | J7: =Lcode_mapping!K7 -> Session | ... V7: =Lcode_mapping!W7 -> -
A8: =Lcode_mapping!A8 -> 123 | B8: =Lcode_mapping!B8 -> 1 | C8: =Lcode_mapping!D8 -> CORRTYPE | D8: =Lcode_mapping!E8 -> 4 | E8: =Lcode_mapping!F8 -> 1 | F8: =Lcode_mapping!G8 -> 1 | G8: =Lcode_mapping!H8 -> A | H8: =Lcode_mapping!I8 -> 1 | I8: =Lcode_mapping!J8 -> Correlator type: MK3/MK4/K4 etc. | J8: =Lcode_mapping!K8 -> Session | ... V8: =Lcode_mapping!W8 -> -
A9: =Lcode_mapping!A9 -> 125 | B9: =Lcode_mapping!B9 -> 1 | C9: =Lcode_mapping!D9 -> EXPDESC | D9: =Lcode_mapping!E9 -> 40 | E9: =Lcode_mapping!F9 -> 1 | F9: =Lcode_mapping!G9 -> 1 | G9: =Lcode_mapping!H9 -> A | H9: =Lcode_mapping!I9 -> 1 | I9: =Lcode_mapping!J9 -> Experiment description. | J9: =Lcode_mapping!K9 -> Session | ... V9: =Lcode_mapping!W9 -> -
A10: =Lcode_mapping!A10 -> 124 | B10: =Lcode_mapping!B10 -> 1 | C10: =Lcode_mapping!D10 -> EXPCODE | D10: =Lcode_mapping!E10 -> 16 | E10: =Lcode_mapping!F10 -> 1 | F10: =Lcode_mapping!G10 -> 1 | G10: =Lcode_mapping!H10 -> A | H10: =Lcode_mapping!I10 -> 1 | I10: =Lcode_mapping!J10 -> Experiment name. | J10: =Lcode_mapping!K10 -> Session | ... V10: =Lcode_mapping!W10 -> -
A11: =Lcode_mapping!A11 -> 126 | B11: =Lcode_mapping!B11 -> 1 | C11: =Lcode_mapping!D11 -> EXPSERNO | D11: =Lcode_mapping!E11 -> 1 | E11: =Lcode_mapping!F11 -> 1 | F11: =Lcode_mapping!G11 -> 1 | G11: =Lcode_mapping!H11 -> I | H11: =Lcode_mapping!I11 -> 1 | I11: =Lcode_mapping!J11 -> Experiment Serial Number. | J11: =Lcode_mapping!K11 -> Session | ... V11: =Lcode_mapping!W11 -> -
A12: =Lcode_mapping!A12 -> 128 | B12: =Lcode_mapping!B12 -> 1 | C12: =Lcode_mapping!D12 -> INTRVAL4 | D12: =Lcode_mapping!E12 -> 5 | E12: =Lcode_mapping!F12 -> 2 | F12: =Lcode_mapping!G12 -> 1 | G12: =Lcode_mapping!H12 -> I | H12: =Lcode_mapping!I12 -> 1 | I12: =Lcode_mapping!J12 -> First last UTC tag 4 digit year | J12: =Lcode_mapping!K12 -> Session | ... V12: =Lcode_mapping!W12 -> -
... A507: =Lcode_mapping!A507 -> 60 | B507: =Lcode_mapping!B507 -> 2 | C507: =Lcode_mapping!D507 -> MARI.WET | D507: =Lcode_mapping!E507 -> 2 | E507: =Lcode_mapping!F507 -> 2 | F507: =Lcode_mapping!G507 -> 2 | G507: =Lcode_mapping!H507 -> R | H507: =Lcode_mapping!I507 -> 1 | I507: =Lcode_mapping!J507 -> WET COMP OF MARI | J507: =Lcode_mapping!K507 -> Station | ... V507: =Lcode_mapping!W507 -> -

Sheet FileOrder
B1: 14 | C1: 13 | D1: 9 | E1: 1 | F1: 6 | G1: 3 | H1: 4 | I1: 5 | J1: 25
A2: OpenDB Name | B2: File | C2: Directory | D2: Scope | E2: Variable | F2: Type | G2: Dimension | J2: Description
B3: =VLOOKUP($A3,Lcode_mapping!$C:$AA,B$1,FALSE) -> #N/A | C3: =VLOOKUP($A3,Lcode_mapping!$C:$AA,C$1,FALSE) -> #N/A | D3: =VLOOKUP($A3,Lcode_mapping!$C:$AA,D$1,FALSE) -> #N/A | E3: =VLOOKUP($A3,Lcode_mapping!$C:$AA,E$1,FALSE) -> #N/A | F3: =VLOOKUP($A3,Lcode_mapping!$C:$AA,F$1,FALSE) -> #N/A | G3: =VLOOKUP($A3,Lcode_mapping!$C:$AA,G$1,FALSE) -> #N/A | H3: =VLOOKUP($A3,Lcode_mapping!$C:$AA,H$1,FALSE) -> #N/A | I3: =VLOOKUP($A3,Lcode_mapping!$C:$AA,I$1,FALSE) -> #N/A | J3: =VLOOKUP($A3,Lcode_mapping!$C:$AA,J$1,FALSE) -> #N/A
A4: AtmInterval | B4: =VLOOKUP($A4,Lcode_mapping!$C:$AA,B$1,FALSE) -> AtmSetup | C4: =VLOOKUP($A4,Lcode_mapping!$C:$AA,C$1,FALSE) -> Solve | D4: =VLOOKUP($A4,Lcode_mapping!$C:$AA,D$1,FALSE) -> Session | E4: =VLOOKUP($A4,Lcode_mapping!$C:$AA,E$1,FALSE) -> AtmInterval | F4: =VLOOKUP($A4,Lcode_mapping!$C:$AA,F$1,FALSE) -> R | G4: =VLOOKUP($A4,Lcode_mapping!$C:$AA,G$1,FALSE) -> 1 | H4: =VLOOKUP($A4,Lcode_mapping!$C:$AA,H$1,FALSE) -> 1 | I4: =VLOOKUP($A4,Lcode_mapping!$C:$AA,I$1,FALSE) -> 1 | J4: =VLOOKUP($A4,Lcode_mapping!$C:$AA,J$1,FALSE) -> Batchmode atmos interval - hours
A5: AtmRateConstraint | B5: =VLOOKUP($A5,Lcode_mapping!$C:$AA,B$1,FALSE) -> AtmSetup | C5: =VLOOKUP($A5,Lcode_mapping!$C:$AA,C$1,FALSE) -> Solve | D5: =VLOOKUP($A5,Lcode_mapping!$C:$AA,D$1,FALSE) -> Session | E5: =VLOOKUP($A5,Lcode_mapping!$C:$AA,E$1,FALSE) -> AtmRateConstraint | F5: =VLOOKUP($A5,Lcode_mapping!$C:$AA,F$1,FALSE) -> R | G5: =VLOOKUP($A5,Lcode_mapping!$C:$AA,G$1,FALSE) -> 1 | H5: =VLOOKUP($A5,Lcode_mapping!$C:$AA,H$1,FALSE) -> 1 | I5: =VLOOKUP($A5,Lcode_mapping!$C:$AA,I$1,FALSE) -> 1 | J5: =VLOOKUP($A5,Lcode_mapping!$C:$AA,J$1,FALSE) -> Atmosphere constraint. ps/hr
A6: AtmRateSite | B6: =VLOOKUP($A6,Lcode_mapping!$C:$AA,B$1,FALSE) -> #N/A | C6: =VLOOKUP($A6,Lcode_mapping!$C:$AA,C$1,FALSE) -> #N/A | D6: =VLOOKUP($A6,Lcode_mapping!$C:$AA,D$1,FALSE) -> #N/A | E6: =VLOOKUP($A6,Lcode_mapping!$C:$AA,E$1,FALSE) -> #N/A | F6: =VLOOKUP($A6,Lcode_mapping!$C:$AA,F$1,FALSE) -> #N/A | G6: =VLOOKUP($A6,Lcode_mapping!$C:$AA,G$1,FALSE) -> #N/A | H6: =VLOOKUP($A6,Lcode_mapping!$C:$AA,H$1,FALSE) -> #N/A | I6: =VLOOKUP($A6,Lcode_mapping!$C:$AA,I$1,FALSE) -> #N/A | J6: =VLOOKUP($A6,Lcode_mapping!$C:$AA,J$1,FALSE) -> #N/A
A7: GradOffsetConstraint | B7: =VLOOKUP($A7,Lcode_mapping!$C:$AA,B$1,FALSE) -> AtmSetup | C7: =VLOOKUP($A7,Lcode_mapping!$C:$AA,C$1,FALSE) -> Solve | D7: =VLOOKUP($A7,Lcode_mapping!$C:$AA,D$1,FALSE) -> Session | E7: =VLOOKUP($A7,Lcode_mapping!$C:$AA,E$1,FALSE) -> GradOffsetConstraint | F7: =VLOOKUP($A7,Lcode_mapping!$C:$AA,F$1,FALSE) -> R | G7: =VLOOKUP($A7,Lcode_mapping!$C:$AA,G$1,FALSE) -> 1 | H7: =VLOOKUP($A7,Lcode_mapping!$C:$AA,H$1,FALSE) -> 1 | I7: =VLOOKUP($A7,Lcode_mapping!$C:$AA,I$1,FALSE) -> 1 | J7: =VLOOKUP($A7,Lcode_mapping!$C:$AA,J$1,FALSE) -> Gradient Offset Constraint
A8: GradRateConstraint | B8: =VLOOKUP($A8,Lcode_mapping!$C:$AA,B$1,FALSE) -> AtmSetup | C8: =VLOOKUP($A8,Lcode_mapping!$C:$AA,C$1,FALSE) -> Solve | D8: =VLOOKUP($A8,Lcode_mapping!$C:$AA,D$1,FALSE) -> Session | E8: =VLOOKUP($A8,Lcode_mapping!$C:$AA,E$1,FALSE) -> GradRateConstraint | F8: =VLOOKUP($A8,Lcode_mapping!$C:$AA,F$1,FALSE) -> R | G8: =VLOOKUP($A8,Lcode_mapping!$C:$AA,G$1,FALSE) -> 1 | H8: =VLOOKUP($A8,Lcode_mapping!$C:$AA,H$1,FALSE) -> 1 | I8: =VLOOKUP($A8,Lcode_mapping!$C:$AA,I$1,FALSE) -> 1 | J8: =VLOOKUP($A8,Lcode_mapping!$C:$AA,J$1,FALSE) -> Gradient Rate Constraint
A9: AzTheo | B9: =VLOOKUP($A9,Lcode_mapping!$C:$AA,B$1,FALSE) -> AzEl | C9: =VLOOKUP($A9,Lcode_mapping!$C:$AA,C$1,FALSE) -> - | D9: =VLOOKUP($A9,Lcode_mapping!$C:$AA,D$1,FALSE) -> Station | E9: =VLOOKUP($A9,Lcode_mapping!$C:$AA,E$1,FALSE) -> AzTheo | F9: =VLOOKUP($A9,Lcode_mapping!$C:$AA,F$1,FALSE) -> R | G9: =VLOOKUP($A9,Lcode_mapping!$C:$AA,G$1,FALSE) -> 2 | H9: =VLOOKUP($A9,Lcode_mapping!$C:$AA,H$1,FALSE) -> 2 | I9: =VLOOKUP($A9,Lcode_mapping!$C:$AA,I$1,FALSE) -> 1 | J9: =VLOOKUP($A9,Lcode_mapping!$C:$AA,J$1,FALSE) -> Azimuth array definition
A10: ElTheo | B10: =VLOOKUP($A10,Lcode_mapping!$C:$AA,B$1,FALSE) -> AzEl | C10: =VLOOKUP($A10,Lcode_mapping!$C:$AA,C$1,FALSE) -> - | D10: =VLOOKUP($A10,Lcode_mapping!$C:$AA,D$1,FALSE) -> Station | E10: =VLOOKUP($A10,Lcode_mapping!$C:$AA,E$1,FALSE) -> ElTheo | F10: =VLOOKUP($A10,Lcode_mapping!$C:$AA,F$1,FALSE) -> R | G10: =VLOOKUP($A10,Lcode_mapping!$C:$AA,G$1,FALSE) -> 2 | H10: =VLOOKUP($A10,Lcode_mapping!$C:$AA,H$1,FALSE) -> 2 | I10: =VLOOKUP($A10,Lcode_mapping!$C:$AA,I$1,FALSE) -> 1 | J10: =VLOOKUP($A10,Lcode_mapping!$C:$AA,J$1,FALSE) -> Elevation array definition
A11: Baseline | B11: =VLOOKUP($A11,Lcode_mapping!$C:$AA,B$1,FALSE) -> Baseline | C11: =VLOOKUP($A11,Lcode_mapping!$C:$AA,C$1,FALSE) -> Observables | D11: =VLOOKUP($A11,Lcode_mapping!$C:$AA,D$1,FALSE) -> OBs | E11: =VLOOKUP($A11,Lcode_mapping!$C:$AA,E$1,FALSE) -> Baseline | F11: =VLOOKUP($A11,Lcode_mapping!$C:$AA,F$1,FALSE) -> A | G11: =VLOOKUP($A11,Lcode_mapping!$C:$AA,G$1,FALSE) -> 4 | H11: =VLOOKUP($A11,Lcode_mapping!$C:$AA,H$1,FALSE) -> 2 | I11: =VLOOKUP($A11,Lcode_mapping!$C:$AA,I$1,FALSE) -> 1 | J11: =VLOOKUP($A11,Lcode_mapping!$C:$AA,J$1,FALSE) -> Ref and rem site names.
A12: BaselineClock | B12: =VLOOKUP($A12,Lcode_mapping!$C:$AA,B$1,FALSE) -> #N/A | C12: =VLOOKUP($A12,Lcode_mapping!$C:$AA,C$1,FALSE) -> #N/A | D12: =VLOOKUP($A12,Lcode_mapping!$C:$AA,D$1,FALSE) -> #N/A | E12: =VLOOKUP($A12,Lcode_mapping!$C:$AA,E$1,FALSE) -> #N/A | F12: =VLOOKUP($A12,Lcode_mapping!$C:$AA,F$1,FALSE) -> #N/A | G12: =VLOOKUP($A12,Lcode_mapping!$C:$AA,G$1,FALSE) -> #N/A | H12: =VLOOKUP($A12,Lcode_mapping!$C:$AA,H$1,FALSE) -> #N/A | I12: =VLOOKUP($A12,Lcode_mapping!$C:$AA,I$1,FALSE) -> #N/A | J12: =VLOOKUP($A12,Lcode_mapping!$C:$AA,J$1,FALSE) -> #N/A
A13: AxisOffsetCal | B13: =VLOOKUP($A13,Lcode_mapping!$C:$AA,B$1,FALSE) -> #N/A | C13: =VLOOKUP($A13,Lcode_mapping!$C:$AA,C$1,FALSE) -> #N/A | D13: =VLOOKUP($A13,Lcode_mapping!$C:$AA,D$1,FALSE) -> #N/A | E13: =VLOOKUP($A13,Lcode_mapping!$C:$AA,E$1,FALSE) -> #N/A | F13: =VLOOKUP($A13,Lcode_mapping!$C:$AA,F$1,FALSE) -> #N/A | G13: =VLOOKUP($A13,Lcode_mapping!$C:$AA,G$1,FALSE) -> #N/A | H13: =VLOOKUP($A13,Lcode_mapping!$C:$AA,H$1,FALSE) -> #N/A | I13: =VLOOKUP($A13,Lcode_mapping!$C:$AA,I$1,FALSE) -> #N/A | J13: =VLOOKUP($A13,Lcode_mapping!$C:$AA,J$1,FALSE) -> #N/A
A14: BendCal | B14: =VLOOKUP($A14,Lcode_mapping!$C:$AA,B$1,FALSE) -> #N/A | C14: =VLOOKUP($A14,Lcode_mapping!$C:$AA,C$1,FALSE) -> #N/A | D14: =VLOOKUP($A14,Lcode_mapping!$C:$AA,D$1,FALSE) -> #N/A | E14: =VLOOKUP($A14,Lcode_mapping!$C:$AA,E$1,FALSE) -> #N/A | F14: =VLOOKUP($A14,Lcode_mapping!$C:$AA,F$1,FALSE) -> #N/A | G14: =VLOOKUP($A14,Lcode_mapping!$C:$AA,G$1,FALSE) -> #N/A | H14: =VLOOKUP($A14,Lcode_mapping!$C:$AA,H$1,FALSE) -> #N/A | I14: =VLOOKUP($A14,Lcode_mapping!$C:$AA,I$1,FALSE) -> #N/A | J14: =VLOOKUP($A14,Lcode_mapping!$C:$AA,J$1,FALSE) -> #N/A
A15: BendSunCal | B15: =VLOOKUP($A15,Lcode_mapping!$C:$AA,B$1,FALSE) -> #N/A | C15: =VLOOKUP($A15,Lcode_mapping!$C:$AA,C$1,FALSE) -> #N/A | D15: =VLOOKUP($A15,Lcode_mapping!$C:$AA,D$1,FALSE) -> #N/A | E15: =VLOOKUP($A15,Lcode_mapping!$C:$AA,E$1,FALSE) -> #N/A | F15: =VLOOKUP($A15,Lcode_mapping!$C:$AA,F$1,FALSE) -> #N/A | G15: =VLOOKUP($A15,Lcode_mapping!$C:$AA,G$1,FALSE) -> #N/A | H15: =VLOOKUP($A15,Lcode_mapping!$C:$AA,H$1,FALSE) -> #N/A | I15: =VLOOKUP($A15,Lcode_mapping!$C:$AA,I$1,FALSE) -> #N/A | J15: =VLOOKUP($A15,Lcode_mapping!$C:$AA,J$1,FALSE) -> #N/A
... A243: FeedRotation | B243: =VLOOKUP($A243,Lcode_mapping!$C:$AA,B$1,FALSE) -> FeedRotation | C243: =VLOOKUP($A243,Lcode_mapping!$C:$AA,C$1,FALSE) -> - | D243: =VLOOKUP($A243,Lcode_mapping!$C:$AA,D$1,FALSE) -> Station | E243: =VLOOKUP($A243,Lcode_mapping!$C:$AA,E$1,FALSE) -> FeedRotation | F243: =VLOOKUP($A243,Lcode_mapping!$C:$AA,F$1,FALSE) -> R | G243: =VLOOKUP($A243,Lcode_mapping!$C:$AA,G$1,FALSE) -> 2 | H243: =VLOOKUP($A243,Lcode_mapping!$C:$AA,H$1,FALSE) -> 1 | I243: =VLOOKUP($A243,Lcode_mapping!$C:$AA,I$1,FALSE) -> 1 | J243: =VLOOKUP($A243,Lcode_mapping!$C:$AA,J$1,FALSE) -> Feedhorn rotation angle.
A244: FractC | B244: FractC | C244: =VLOOKUP($A244,Lcode_mapping!$C:$AA,C$1,FALSE) -> Solve | D244: =VLOOKUP($A244,Lcode_mapping!$C:$AA,D$1,FALSE) -> Obs | E244: =VLOOKUP($A244,Lcode_mapping!$C:$AA,E$1,FALSE) -> FractC | F244: =VLOOKUP($A244,Lcode_mapping!$C:$AA,F$1,FALSE) -> R | G244: =VLOOKUP($A244,Lcode_mapping!$C:$AA,G$1,FALSE) -> 1 | H244: =VLOOKUP($A244,Lcode_mapping!$C:$AA,H$1,FALSE) -> 1 | I244: =VLOOKUP($A244,Lcode_mapping!$C:$AA,I$1,FALSE) -> 1 | J244: =VLOOKUP($A244,Lcode_mapping!$C:$AA,J$1,FALSE) -> Coordinate time at site 1
A245: GroupBLWeightName | B245: =VLOOKUP($A245,Lcode_mapping!$C:$AA,B$1,FALSE) -> #N/A | C245: =VLOOKUP($A245,Lcode_mapping!$C:$AA,C$1,FALSE) -> #N/A | D245: =VLOOKUP($A245,Lcode_mapping!$C:$AA,D$1,FALSE) -> #N/A | E245: =VLOOKUP($A245,Lcode_mapping!$C:$AA,E$1,FALSE) -> #N/A | F245: =VLOOKUP($A245,Lcode_mapping!$C:$AA,F$1,FALSE) -> #N/A | G245: =VLOOKUP($A245,Lcode_mapping!$C:$AA,G$1,FALSE) -> #N/A | H245: =VLOOKUP($A245,Lcode_mapping!$C:$AA,H$1,FALSE) -> #N/A | I245: =VLOOKUP($A245,Lcode_mapping!$C:$AA,I$1,FALSE) -> #N/A | J245: =VLOOKUP($A245,Lcode_mapping!$C:$AA,J$1,FALSE) -> #N/A
A246: GroupBLWeights | B246: =VLOOKUP($A246,Lcode_mapping!$C:$AA,B$1,FALSE) -> GroupBLWeights | C246: =VLOOKUP($A246,Lcode_mapping!$C:$AA,C$1,FALSE) -> Session | D246: =VLOOKUP($A246,Lcode_mapping!$C:$AA,D$1,FALSE) -> Session | E246: =VLOOKUP($A246,Lcode_mapping!$C:$AA,E$1,FALSE) -> GroupBLWeights | F246: =VLOOKUP($A246,Lcode_mapping!$C:$AA,F$1,FALSE) -> R | G246: =VLOOKUP($A246,Lcode_mapping!$C:$AA,G$1,FALSE) -> 2 | H246: =VLOOKUP($A246,Lcode_mapping!$C:$AA,H$1,FALSE) -> 55 | I246: =VLOOKUP($A246,Lcode_mapping!$C:$AA,I$1,FALSE) -> 1 | J246: =VLOOKUP($A246,Lcode_mapping!$C:$AA,J$1,FALSE) -> Group delay and rate re-weighting constants.
A247: GroupDelaySig | B247: =VLOOKUP($A247,Lcode_mapping!$C:$AA,B$1,FALSE) -> GroupDelay_bS | C247: =VLOOKUP($A247,Lcode_mapping!$C:$AA,C$1,FALSE) -> Observables | D247: =VLOOKUP($A247,Lcode_mapping!$C:$AA,D$1,FALSE) -> Obs | E247: =VLOOKUP($A247,Lcode_mapping!$C:$AA,E$1,FALSE) -> GroupDelaySig | F247: =VLOOKUP($A247,Lcode_mapping!$C:$AA,F$1,FALSE) -> R | G247: =VLOOKUP($A247,Lcode_mapping!$C:$AA,G$1,FALSE) -> 1 | H247: =VLOOKUP($A247,Lcode_mapping!$C:$AA,H$1,FALSE) -> 1 | I247: =VLOOKUP($A247,Lcode_mapping!$C:$AA,I$1,FALSE) -> 1 | J247: =VLOOKUP($A247,Lcode_mapping!$C:$AA,J$1,FALSE) -> Delay Measurement Sigma
A248: GroupDelayFull | B248: =VLOOKUP($A248,Lcode_mapping!$C:$AA,B$1,FALSE) -> GroupDelayFull_bS | C248: =VLOOKUP($A248,Lcode_mapping!$C:$AA,C$1,FALSE) -> ObsEdit | D248: =VLOOKUP($A248,Lcode_mapping!$C:$AA,D$1,FALSE) -> Obs | E248: =VLOOKUP($A248,Lcode_mapping!$C:$AA,E$1,FALSE) -> GroupDelayFull | F248: =VLOOKUP($A248,Lcode_mapping!$C:$AA,F$1,FALSE) -> R | G248: =VLOOKUP($A248,Lcode_mapping!$C:$AA,G$1,FALSE) -> 1 | H248: =VLOOKUP($A248,Lcode_mapping!$C:$AA,H$1,FALSE) -> 1 | I248: =VLOOKUP($A248,Lcode_mapping!$C:$AA,I$1,FALSE) -> 1 | J248: =VLOOKUP($A248,Lcode_mapping!$C:$AA,J$1,FALSE) -> Delay Observable with ambiguities resolved and added.
A249: DataFlag | B249: =VLOOKUP($A249,Lcode_mapping!$C:$AA,B$1,FALSE) -> DataFlag_bS | C249: =VLOOKUP($A249,Lcode_mapping!$C:$AA,C$1,FALSE) -> Observables | D249: =VLOOKUP($A249,Lcode_mapping!$C:$AA,D$1,FALSE) -> Obs | E249: =VLOOKUP($A249,Lcode_mapping!$C:$AA,E$1,FALSE) -> DataFlag | F249: =VLOOKUP($A249,Lcode_mapping!$C:$AA,F$1,FALSE) -> I | G249: =VLOOKUP($A249,Lcode_mapping!$C:$AA,G$1,FALSE) -> 1 | H249: =VLOOKUP($A249,Lcode_mapping!$C:$AA,H$1,FALSE) -> 1 | I249: =VLOOKUP($A249,Lcode_mapping!$C:$AA,I$1,FALSE) -> 1 | J249: =VLOOKUP($A249,Lcode_mapping!$C:$AA,J$1,FALSE) -> 0=OK, -1=Missing, -2=bad,-3=sigma small, -4=sigma big
A250: GroupRate | B250: =VLOOKUP($A250,Lcode_mapping!$C:$AA,B$1,FALSE) -> GroupRate_bS | C250: =VLOOKUP($A250,Lcode_mapping!$C:$AA,C$1,FALSE) -> Observables | D250: =VLOOKUP($A250,Lcode_mapping!$C:$AA,D$1,FALSE) -> Obs | E250: =VLOOKUP($A250,Lcode_mapping!$C:$AA,E$1,FALSE) -> GroupRate | F250: =VLOOKUP($A250,Lcode_mapping!$C:$AA,F$1,FALSE) -> R | G250: =VLOOKUP($A250,Lcode_mapping!$C:$AA,G$1,FALSE) -> 1 | H250: =VLOOKUP($A250,Lcode_mapping!$C:$AA,H$1,FALSE) -> 1 | I250: =VLOOKUP($A250,Lcode_mapping!$C:$AA,I$1,FALSE) -> 1 | J250: =VLOOKUP($A250,Lcode_mapping!$C:$AA,J$1,FALSE) -> Rate Observable
A251: GroupRateSig | B251: =VLOOKUP($A251,Lcode_mapping!$C:$AA,B$1,FALSE) -> GroupRate_bS | C251: =VLOOKUP($A251,Lcode_mapping!$C:$AA,C$1,FALSE) -> Observables | D251: =VLOOKUP($A251,Lcode_mapping!$C:$AA,D$1,FALSE) -> Obs | E251: =VLOOKUP($A251,Lcode_mapping!$C:$AA,E$1,FALSE) -> GroupRateSig | F251: =VLOOKUP($A251,Lcode_mapping!$C:$AA,F$1,FALSE) -> R | G251: =VLOOKUP($A251,Lcode_mapping!$C:$AA,G$1,FALSE) -> 1 | H251: =VLOOKUP($A251,Lcode_mapping!$C:$AA,H$1,FALSE) -> 1 | I251: =VLOOKUP($A251,Lcode_mapping!$C:$AA,I$1,FALSE) -> 1 | J251: =VLOOKUP($A251,Lcode_mapping!$C:$AA,J$1,FALSE) -> Rate Measurement Sigma
A252: Correlator | B252: =VLOOKUP($A252,Lcode_mapping!$C:$AA,B$1,FALSE) -> Head | C252: =VLOOKUP($A252,Lcode_mapping!$C:$AA,C$1,FALSE) -> - | D252: =VLOOKUP($A252,Lcode_mapping!$C:$AA,D$1,FALSE) -> Session | E252: =VLOOKUP($A252,Lcode_mapping!$C:$AA,E$1,FALSE) -> Correlator | F252: =VLOOKUP($A252,Lcode_mapping!$C:$AA,F$1,FALSE) -> A | G252: =VLOOKUP($A252,Lcode_mapping!$C:$AA,G$1,FALSE) -> 16 | H252: =VLOOKUP($A252,Lcode_mapping!$C:$AA,H$1,FALSE) -> 1 | I252: =VLOOKUP($A252,Lcode_mapping!$C:$AA,I$1,FALSE) -> 1 | J252: =VLOOKUP($A252,Lcode_mapping!$C:$AA,J$1,FALSE) -> Correlator name.
A253: CorrelatorType | B253: =VLOOKUP($A253,Lcode_mapping!$C:$AA,B$1,FALSE) -> Head | C253: =VLOOKUP($A253,Lcode_mapping!$C:$AA,C$1,FALSE) -> - | D253: =VLOOKUP($A253,Lcode_mapping!$C:$AA,D$1,FALSE) -> Session | E253: =VLOOKUP($A253,Lcode_mapping!$C:$AA,E$1,FALSE) -> CorrelatorType | F253: =VLOOKUP($A253,Lcode_mapping!$C:$AA,F$1,FALSE) -> A | G253: =VLOOKUP($A253,Lcode_mapping!$C:$AA,G$1,FALSE) -> 4 | H253: =VLOOKUP($A253,Lcode_mapping!$C:$AA,H$1,FALSE) -> 1 | I253: =VLOOKUP($A253,Lcode_mapping!$C:$AA,I$1,FALSE) -> 1 | J253: =VLOOKUP($A253,Lcode_mapping!$C:$AA,J$1,FALSE) -> Correlator type: MK3/MK4/K4 etc.
A254: ExpDescription | B254: =VLOOKUP($A254,Lcode_mapping!$C:$AA,B$1,FALSE) -> Head | C254: =VLOOKUP($A254,Lcode_mapping!$C:$AA,C$1,FALSE) -> - | D254: =VLOOKUP($A254,Lcode_mapping!$C:$AA,D$1,FALSE) -> Session | E254: =VLOOKUP($A254,Lcode_mapping!$C:$AA,E$1,FALSE) -> ExpDescription | F254: =VLOOKUP($A254,Lcode_mapping!$C:$AA,F$1,FALSE) -> A | G254: =VLOOKUP($A254,Lcode_mapping!$C:$AA,G$1,FALSE) -> 40 | H254: =VLOOKUP($A254,Lcode_mapping!$C:$AA,H$1,FALSE) -> 1 | I254: =VLOOKUP($A254,Lcode_mapping!$C:$AA,I$1,FALSE) -> 1 | J254: =VLOOKUP($A254,Lcode_mapping!$C:$AA,J$1,FALSE) -> Experiment description.
A255: ExpSerialNumber | B255: =VLOOKUP($A255,Lcode_mapping!$C:$AA,B$1,FALSE) -> Head | C255: =VLOOKUP($A255,Lcode_mapping!$C:$AA,C$1,FALSE) -> - | D255: =VLOOKUP($A255,Lcode_mapping!$C:$AA,D$1,FALSE) -> Session | E255: =VLOOKUP($A255,Lcode_mapping!$C:$AA,E$1,FALSE) -> ExpSerialNumber | F255: =VLOOKUP($A255,Lcode_mapping!$C:$AA,F$1,FALSE) -> I | G255: =VLOOKUP($A255,Lcode_mapping!$C:$AA,G$1,FALSE) -> 1 | H255: =VLOOKUP($A255,Lcode_mapping!$C:$AA,H$1,FALSE) -> 1 | I255: =VLOOKUP($A255,Lcode_mapping!$C:$AA,I$1,FALSE) -> 1 | J255: =VLOOKUP($A255,Lcode_mapping!$C:$AA,J$1,FALSE) -> Experiment Serial Number.
A256: iUTCInterval | B256: =VLOOKUP($A256,Lcode_mapping!$C:$AA,B$1,FALSE) -> Head | C256: =VLOOKUP($A256,Lcode_mapping!$C:$AA,C$1,FALSE) -> - | D256: =VLOOKUP($A256,Lcode_mapping!$C:$AA,D$1,FALSE) -> Session | E256: =VLOOKUP($A256,Lcode_mapping!$C:$AA,E$1,FALSE) -> iUTCInterval | F256: =VLOOKUP($A256,Lcode_mapping!$C:$AA,F$1,FALSE) -> I | G256: =VLOOKUP($A256,Lcode_mapping!$C:$AA,G$1,FALSE) -> 5 | H256: =VLOOKUP($A256,Lcode_mapping!$C:$AA,H$1,FALSE) -> 2 | I256: =VLOOKUP($A256,Lcode_mapping!$C:$AA,I$1,FALSE) -> 1 | J256: =VLOOKUP($A256,Lcode_mapping!$C:$AA,J$1,FALSE) -> First and last UTC time tag in input file.
... A348: Tsys | B348: =VLOOKUP($A348,Lcode_mapping!$C:$AA,B$1,FALSE) -> Tsys | C348: =VLOOKUP($A348,Lcode_mapping!$C:$AA,C$1,FALSE) -> Observables | D348: =VLOOKUP($A348,Lcode_mapping!$C:$AA,D$1,FALSE) -> Obs | E348: =VLOOKUP($A348,Lcode_mapping!$C:$AA,E$1,FALSE) -> Tsys | F348: =VLOOKUP($A348,Lcode_mapping!$C:$AA,F$1,FALSE) -> R | G348: =VLOOKUP($A348,Lcode_mapping!$C:$AA,G$1,FALSE) -> 16 | H348: =VLOOKUP($A348,Lcode_mapping!$C:$AA,H$1,FALSE) -> 2 | I348: =VLOOKUP($A348,Lcode_mapping!$C:$AA,I$1,FALSE) -> 1 | J348: =VLOOKUP($A348,Lcode_mapping!$C:$AA,J$1,FALSE) -> TSYS TMP (K) 14CH AND IF1 IF2
A349: UNCALDLY | B349: UNCALDLY | C349: =VLOOKUP($A349,Lcode_mapping!$C:$AA,C$1,FALSE) -> - | D349: =VLOOKUP($A349,Lcode_mapping!$C:$AA,D$1,FALSE) -> Obs | E349: =VLOOKUP($A349,Lcode_mapping!$C:$AA,E$1,FALSE) -> UNCALDLY | F349: =VLOOKUP($A349,Lcode_mapping!$C:$AA,F$1,FALSE) -> R | G349: =VLOOKUP($A349,Lcode_mapping!$C:$AA,G$1,FALSE) -> 1 | H349: =VLOOKUP($A349,Lcode_mapping!$C:$AA,H$1,FALSE) -> 1 | I349: =VLOOKUP($A349,Lcode_mapping!$C:$AA,I$1,FALSE) -> 1 | J349: =VLOOKUP($A349,Lcode_mapping!$C:$AA,J$1,FALSE) -> Bad Phase Cal Delay. Removed from Obs.
A350: UNPHAFLG | B350: UNPHAFLG | C350: =VLOOKUP($A350,Lcode_mapping!$C:$AA,C$1,FALSE) -> Solve | D350: =VLOOKUP($A350,Lcode_mapping!$C:$AA,D$1,FALSE) -> Obs | E350: =VLOOKUP($A350,Lcode_mapping!$C:$AA,E$1,FALSE) -> UNPHAFLG | F350: =VLOOKUP($A350,Lcode_mapping!$C:$AA,F$1,FALSE) -> I | G350: =VLOOKUP($A350,Lcode_mapping!$C:$AA,G$1,FALSE) -> 2 | H350: =VLOOKUP($A350,Lcode_mapping!$C:$AA,H$1,FALSE) -> 2 | I350: =VLOOKUP($A350,Lcode_mapping!$C:$AA,I$1,FALSE) -> 1 | J350: =VLOOKUP($A350,Lcode_mapping!$C:$AA,J$1,FALSE) -> UnPhaseCal flag
A351: URVR | B351: URVR | C351: =VLOOKUP($A351,Lcode_mapping!$C:$AA,C$1,FALSE) -> Observables | D351: =VLOOKUP($A351,Lcode_mapping!$C:$AA,D$1,FALSE) -> Obs | E351: =VLOOKUP($A351,Lcode_mapping!$C:$AA,E$1,FALSE) -> URVR | F351: =VLOOKUP($A351,Lcode_mapping!$C:$AA,F$1,FALSE) -> R | G351: =VLOOKUP($A351,Lcode_mapping!$C:$AA,G$1,FALSE) -> 2 | H351: =VLOOKUP($A351,Lcode_mapping!$C:$AA,H$1,FALSE) -> 1 | I351: =VLOOKUP($A351,Lcode_mapping!$C:$AA,I$1,FALSE) -> 1 | J351: =VLOOKUP($A351,Lcode_mapping!$C:$AA,J$1,FALSE) -> Rate derivatives mHz per asec.
A352: UVFperAsec | B352: UVFperAsec | C352: =VLOOKUP($A352,Lcode_mapping!$C:$AA,C$1,FALSE) -> Solve | D352: =VLOOKUP($A352,Lcode_mapping!$C:$AA,D$1,FALSE) -> Obs | E352: =VLOOKUP($A352,Lcode_mapping!$C:$AA,E$1,FALSE) -> UVFperAsec | F352: =VLOOKUP($A352,Lcode_mapping!$C:$AA,F$1,FALSE) -> R | G352: =VLOOKUP($A352,Lcode_mapping!$C:$AA,G$1,FALSE) -> 2 | H352: =VLOOKUP($A352,Lcode_mapping!$C:$AA,H$1,FALSE) -> 1 | I352: =VLOOKUP($A352,Lcode_mapping!$C:$AA,I$1,FALSE) -> 1 | J352: =VLOOKUP($A352,Lcode_mapping!$C:$AA,J$1,FALSE) -> U V in FR per arcsec from CALC
A353: F12VOLT | B353: =VLOOKUP($A353,Lcode_mapping!$C:$AA,B$1,FALSE) -> WVR | C353: =VLOOKUP($A353,Lcode_mapping!$C:$AA,C$1,FALSE) -> - | D353: =VLOOKUP($A353,Lcode_mapping!$C:$AA,D$1,FALSE) -> Station | E353: =VLOOKUP($A353,Lcode_mapping!$C:$AA,E$1,FALSE) -> F12VOLT | F353: =VLOOKUP($A353,Lcode_mapping!$C:$AA,F$1,FALSE) -> R | G353: =VLOOKUP($A353,Lcode_mapping!$C:$AA,G$1,FALSE) -> 2 | H353: =VLOOKUP($A353,Lcode_mapping!$C:$AA,H$1,FALSE) -> 2 | I353: =VLOOKUP($A353,Lcode_mapping!$C:$AA,I$1,FALSE) -> 1 | J353: =VLOOKUP($A353,Lcode_mapping!$C:$AA,J$1,FALSE) -> F1, F2 VOLT .
A354: WVRDelay | B354: =VLOOKUP($A354,Lcode_mapping!$C:$AA,B$1,FALSE) -> WVR | C354: =VLOOKUP($A354,Lcode_mapping!$C:$AA,C$1,FALSE) -> - | D354: =VLOOKUP($A354,Lcode_mapping!$C:$AA,D$1,FALSE) -> Station | E354: =VLOOKUP($A354,Lcode_mapping!$C:$AA,E$1,FALSE) -> WVRDelay | F354: =VLOOKUP($A354,Lcode_mapping!$C:$AA,F$1,FALSE) -> R | G354: =VLOOKUP($A354,Lcode_mapping!$C:$AA,G$1,FALSE) -> 2 | H354: =VLOOKUP($A354,Lcode_mapping!$C:$AA,H$1,FALSE) -> 2 | I354: =VLOOKUP($A354,Lcode_mapping!$C:$AA,I$1,FALSE) -> 2 | J354: =VLOOKUP($A354,Lcode_mapping!$C:$AA,J$1,FALSE) -> WVR line of sight & ZENITH(sec)
A355: WVRQcode | B355: =VLOOKUP($A355,Lcode_mapping!$C:$AA,B$1,FALSE) -> WVR | C355: =VLOOKUP($A355,Lcode_mapping!$C:$AA,C$1,FALSE) -> - | D355: =VLOOKUP($A355,Lcode_mapping!$C:$AA,D$1,FALSE) -> Station | E355: =VLOOKUP($A355,Lcode_mapping!$C:$AA,E$1,FALSE) -> WVRQcode | F355: =VLOOKUP($A355,Lcode_mapping!$C:$AA,F$1,FALSE) -> I | G355: =VLOOKUP($A355,Lcode_mapping!$C:$AA,G$1,FALSE) -> 2 | H355: =VLOOKUP($A355,Lcode_mapping!$C:$AA,H$1,FALSE) -> 1 | I355: =VLOOKUP($A355,Lcode_mapping!$C:$AA,I$1,FALSE) -> 1 | J355: =VLOOKUP($A355,Lcode_mapping!$C:$AA,J$1,FALSE) -> WVR DELAY DATA QUALITY CODE
A356: WVRTemp | B356: =VLOOKUP($A356,Lcode_mapping!$C:$AA,B$1,FALSE) -> WVR | C356: =VLOOKUP($A356,Lcode_mapping!$C:$AA,C$1,FALSE) -> - | D356: =VLOOKUP($A356,Lcode_mapping!$C:$AA,D$1,FALSE) -> Station | E356: =VLOOKUP($A356,Lcode_mapping!$C:$AA,E$1,FALSE) -> WVRTemp | F356: =VLOOKUP($A356,Lcode_mapping!$C:$AA,F$1,FALSE) -> R | G356: =VLOOKUP($A356,Lcode_mapping!$C:$AA,G$1,FALSE) -> 2 | H356: =VLOOKUP($A356,Lcode_mapping!$C:$AA,H$1,FALSE) -> 2 | I356: =VLOOKUP($A356,Lcode_mapping!$C:$AA,I$1,FALSE) -> 1 | J356: =VLOOKUP($A356,Lcode_mapping!$C:$AA,J$1,FALSE) -> BRT TEMP (K) OF WVR ,F1,F2.
A357: WVRTempRef | B357: =VLOOKUP($A357,Lcode_mapping!$C:$AA,B$1,FALSE) -> WVR | C357: =VLOOKUP($A357,Lcode_mapping!$C:$AA,C$1,FALSE) -> - | D357: =VLOOKUP($A357,Lcode_mapping!$C:$AA,D$1,FALSE) -> Station | E357: =VLOOKUP($A357,Lcode_mapping!$C:$AA,E$1,FALSE) -> WVRTempRef | F357: =VLOOKUP($A357,Lcode_mapping!$C:$AA,F$1,FALSE) -> R | G357: =VLOOKUP($A357,Lcode_mapping!$C:$AA,G$1,FALSE) -> 3 | H357: =VLOOKUP($A357,Lcode_mapping!$C:$AA,H$1,FALSE) -> 2 | I357: =VLOOKUP($A357,Lcode_mapping!$C:$AA,I$1,FALSE) -> 1 | J357: =VLOOKUP($A357,Lcode_mapping!$C:$AA,J$1,FALSE) -> REFERENCE1,2 WVR TEMP (K).

Sheet global_toc
B1: Type | D1: D1 | E1: D2 | F1: D3 | G1: K | H1: Des | I1: First | J1: Last | K1: # | M1: Check to see if in lcode_mapping
A2: 1 | B2: 1 | C2: SITERECS | D2: 3 | E2: 3 | F2: 1 | G2: R | H2: Site cartesian coords (m). | I2: 79AUG03XX | J2: 11OCT17XA | K2: 5029 | M2: =VLOOKUP(C2,Lcode_mapping!D:D,1,FALSE) -> SITERECS
A3: 2 | B3: 1 | C3: AXISOFFS | D3: 3 | E3: 1 | F3: 1 | G3: R | H3: Axis offsets (m). | I3: 79AUG03XX | J3: 11OCT17XA | K3: 5029 | M3: =VLOOKUP(C3,Lcode_mapping!D:D,1,FALSE) -> AXISOFFS
A4: 3 | B4: 1 | C4: ETD DATA | D4: 3 | E4: 1 | F4: 1 | G4: R | H4: Earth tide module data (la.,h,l) | I4: 79AUG03XX | J4: 11OCT17XA | K4: 5029 | M4: =VLOOKUP(C4,Lcode_mapping!D:D,1,FALSE) -> ETD DATA
A5: 4 | B5: 1 | C5: PRE DATA | D5: 1 | E5: 1 | F5: 1 | G5: R | H5: Precession constant (asec/cent). | I5: 79AUG03XX | J5: 11OCT17XA | K5: 5029 | M5: =VLOOKUP(C5,Lcode_mapping!D:D,1,FALSE) -> PRE DATA
A6: 5 | B6: 1 | C6: REL DATA | D6: 1 | E6: 1 | F6: 1 | G6: R | H6: Relativity mod data (gamma). | I6: 79AUG03XX | J6: 11OCT17XA | K6: 5029 | M6: =VLOOKUP(C6,Lcode_mapping!D:D,1,FALSE) -> REL DATA
A7: 6 | B7: 1 | C7: PI | D7: 1 | E7: 1 | F7: 1 | G7: R | H7: Pi - to 17 digits accuracy. | I7: 79AUG03XX | J7: 11OCT17XA | K7: 5029 | M7: =VLOOKUP(C7,Lcode_mapping!D:D,1,FALSE) -> PI
A8: 7 | B8: 1 | C8: HALF PI | D8: 1 | E8: 1 | F8: 1 | G8: R | H8: Half pi - to 17 digits accuracy. | I8: 79AUG03XX | J8: 11OCT17XA | K8: 5029 | M8: =VLOOKUP(C8,Lcode_mapping!D:D,1,FALSE) -> HALF PI
A9: 8 | B9: 1 | C9: RAD/DEG | D9: 1 | E9: 1 | F9: 1 | G9: R | H9: Number of radians per degree. | I9: 79AUG03XX | J9: 11OCT17XA | K9: 5003 | M9: =VLOOKUP(C9,Lcode_mapping!D:D,1,FALSE) -> RAD/DEG
A10: 9 | B10: 1 | C10: VLIGHT | D10: 1 | E10: 1 | F10: 1 | G10: R | H10: The speed of light (m/sec). | I10: 79AUG03XX | J10: 11OCT17XA | K10: 5029 | M10: =VLOOKUP(C10,Lcode_mapping!D:D,1,FALSE) -> VLIGHT
A11: 10 | B11: 1 | C11: GAUSS | D11: 1 | E11: 1 | F11: 1 | G11: R | H11: Gauss's constant (rad). | I11: 79AUG03XX | J11: 11OCT17XA | K11: 5029 | M11: =VLOOKUP(C11,Lcode_mapping!D:D,1,FALSE) -> GAUSS
A12: 11 | B12: 1 | C12: ACCELGRV | D12: 1 | E12: 1 | F12: 1 | G12: R | H12: Accel grav at erth surface m/s^2 | I12: 79AUG03XX | J12: 11OCT17XA | K12: 5029 | M12: =VLOOKUP(C12,Lcode_mapping!D:D,1,FALSE) -> ACCELGRV
A13: 12 | B13: 1 | C13: GMSUN | D13: 1 | E13: 1 | F13: 1 | G13: R | H13: GM of the Sun (m^3/sec^2). | I13: 79AUG03XX | J13: 11OCT17XA | K13: 5029 | M13: =VLOOKUP(C13,Lcode_mapping!D:D,1,FALSE) -> GMSUN
... A207: 206 | B207: 1 | C207: RAD TSEC | D207: 1 | E207: 1 | F207: 1 | G207: R | H207: Radians per time second ........ | I207: 08APR17XF | J207: 11JUN23XF | K207: 26 | M207: =VLOOKUP(C207,Lcode_mapping!D:D,1,FALSE) -> RAD TSEC
A208: >>> | C208: >>>>>Begi | G208: t | M208: =VLOOKUP(C208,Lcode_mapping!D:D,1,FALSE) -> #N/A
A209: 1 | B209: 2 | C209: RFREQ | D209: 5 | E209: 1 | F209: 1 | G209: R | H209: RF freq by channel (MHz)........ | I209: 79AUG03XX | J209: 11OCT17XA | K209: 5029 | M209: =VLOOKUP(C209,Lcode_mapping!D:D,1,FALSE) -> RFREQ
A210: 2 | B210: 2 | C210: REF FREQ | D210: 1 | E210: 1 | F210: 1 | G210: R | H210: Freq to which phase is referred. | I210: 79AUG03XX | J210: 11OCT17XA | K210: 5029 | M210: =VLOOKUP(C210,Lcode_mapping!D:D,1,FALSE) -> REF FREQ
A211: 3 | B211: 2 | C211: RAT OBSV | D211: 1 | E211: 1 | F211: 1 | G211: R | H211: Observd delay rate (sec per sec) | I211: 79AUG03XX | J211: 11OCT17XA | K211: 5029 | M211: =VLOOKUP(C211,Lcode_mapping!D:D,1,FALSE) -> RAT OBSV
A212: 4 | B212: 2 | C212: NB DELAY | D212: 1 | E212: 1 | F212: 1 | G212: R | H212: Single band delay (microsec).... | I212: 79AUG03XX | J212: 80APR13X_ | K212: 3 | M212: =VLOOKUP(C212,Lcode_mapping!D:D,1,FALSE) -> NB DELAY
A213: 5 | B213: 2 | C213: AMPBYFRQ | D213: 2 | E213: 5 | F213: 1 | G213: R | H213: Amp(0-1), phs by chan(-180to180) | I213: 79AUG03XX | J213: 11OCT17XA | K213: 4979 | M213: =VLOOKUP(C213,Lcode_mapping!D:D,1,FALSE) -> AMPBYFRQ
A214: 6 | B214: 2 | C214: PHASECAL | D214: 2 | E214: 1 | F214: 1 | G214: R | H214: PC rate by sta ( us per s)...... | I214: 79AUG03XX | J214: 11OCT17XA | K214: 5028 | M214: =VLOOKUP(C214,Lcode_mapping!D:D,1,FALSE) -> PHASECAL
A215: 7 | B215: 2 | C215: DELRESID | D215: 1 | E215: 1 | F215: 1 | G215: R | H215: Delay residual (sec)............ | I215: 79AUG03XX | J215: 11OCT17XA | K215: 5029 | M215: =VLOOKUP(C215,Lcode_mapping!D:D,1,FALSE) -> DELRESID
A216: 8 | B216: 2 | C216: DELSIGMA | D216: 1 | E216: 1 | F216: 1 | G216: R | H216: Delay err (sec)................. | I216: 79AUG03XX | J216: 11OCT17XA | K216: 5029 | M216: =VLOOKUP(C216,Lcode_mapping!D:D,1,FALSE) -> DELSIGMA
A217: 9 | B217: 2 | C217: RATRESID | D217: 1 | E217: 1 | F217: 1 | G217: R | H217: Rate resid (sec per sec)........ | I217: 79AUG03XX | J217: 11OCT17XA | K217: 4987 | M217: =VLOOKUP(C217,Lcode_mapping!D:D,1,FALSE) -> RATRESID
A218: 10 | B218: 2 | C218: RATSIGMA | D218: 1 | E218: 1 | F218: 1 | G218: R | H218: Rate formal error(sec per sec).. | I218: 79AUG03XX | J218: 11OCT17XA | K218: 5029 | M218: =VLOOKUP(C218,Lcode_mapping!D:D,1,FALSE) -> RATSIGMA
A219: 11 | B219: 2 | C219: COHERCOR | D219: 1 | E219: 1 | F219: 1 | G219: R | H219: Corr coeff (0 --> 1)............ | I219: 79AUG03XX | J219: 11OCT17XA | K219: 5029 | M219: =VLOOKUP(C219,Lcode_mapping!D:D,1,FALSE) -> COHERCOR
A220: 12 | B220: 2 | C220: TOTPHASE | D220: 1 | E220: 1 | F220: 1 | G220: R | H220: Total phase degrees mod 360..... | I220: 79AUG03XX | J220: 11OCT17XA | K220: 5029 | M220: =VLOOKUP(C220,Lcode_mapping!D:D,1,FALSE) -> TOTPHASE
... A347: 139 | B347: 2 | C347: PHSUFLAG | D347: 1 | E347: 1 | F347: 1 | G347: I | H347: Phase unweight flag | I347: 80OCT17X_ | J347: 10FEB11XE | K347: 429 | M347: =VLOOKUP(C347,Lcode_mapping!D:D,1,FALSE) -> PHSUFLAG
A348: 140 | B348: 2 | C348: IONPCORR | D348: 1 | E348: 1 | F348: 1 | G348: 4 | H348: Ion corr(phase) Add to theo. sec | I348: 80OCT17X_ | J348: 10FEB11XE | K348: 419 | M348: =VLOOKUP(C348,Lcode_mapping!D:D,1,FALSE) -> IONPCORR
A349: 141 | B349: 2 | C349: #PAMBIG | D349: 1 | E349: 1 | F349: 1 | G349: J | H349: # phase ambiguities | I349: 80OCT17X_ | J349: 10FEB11XE | K349: 446 | M349: =VLOOKUP(C349,Lcode_mapping!D:D,1,FALSE) -> #PAMBIG
A350: 142 | B350: 2 | C350: FROTDLAY | D350: 1 | E350: 1 | F350: 1 | G350: R | H350: Delay due to rel. feed rotation. | I350: 81JAN13XA | J350: 81JAN13XA | K350: 1 | M350: =VLOOKUP(C350,Lcode_mapping!D:D,1,FALSE) -> FROTDLAY
A351: 143 | B351: 2 | C351: IONFACTR | D351: 1 | E351: 1 | F351: 1 | G351: R | H351: S/X DIFFERENCE ION SCALING FACTO | I351: 81JUN16X_ | J351: 81JUN17X_ | K351: 2 | M351: =VLOOKUP(C351,Lcode_mapping!D:D,1,FALSE) -> IONFACTR
A352: 144 | B352: 2 | C352: SB SIGMA | D352: 1 | E352: 1 | F352: 1 | G352: R | H352: SB delay error microseconds..... | I352: 81NOV18X_ | J352: 11OCT17XA | K352: 4939 | M352: =VLOOKUP(C352,Lcode_mapping!D:D,1,FALSE) -> SB SIGMA
A353: 145 | B353: 2 | C353: EXPSERNO | D353: 1 | E353: 1 | F353: 1 | G353: I | H353: Experiment Serial Number........ | I353: 81NOV18X_ | J353: 91NOV27X_ | K353: 519 | M353: =VLOOKUP(C353,Lcode_mapping!D:D,1,FALSE) -> EXPSERNO
A354: 146 | B354: 2 | C354: STARTSEC | D354: 1 | E354: 1 | F354: 1 | G354: R | H354: Start time in sec past hour..... | I354: 82JUN16X_ | J354: 11OCT17XA | K354: 4937 | M354: =VLOOKUP(C354,Lcode_mapping!D:D,1,FALSE) -> STARTSEC
A355: 147 | B355: 2 | C355: STOP SEC | D355: 1 | E355: 1 | F355: 1 | G355: R | H355: Stop time in sec past hour..... | I355: 82JUN16X_ | J355: 11OCT17XA | K355: 4937 | M355: =VLOOKUP(C355,Lcode_mapping!D:D,1,FALSE) -> STOP SEC
A356: 148 | B356: 2 | C356: WVR DELY | D356: 2 | E356: 2 | F356: 2 | G356: R | H356: WVR LINE OF SIGHT & ZENITH(NSEC) | I356: 82JUN16X_ | J356: 84MAY08X_ | K356: 101 | M356: =VLOOKUP(C356,Lcode_mapping!D:D,1,FALSE) -> WVR DELY
A357: 149 | B357: 2 | C357: TOTPHA_S | D357: 1 | E357: 1 | F357: 1 | G357: R | H357: S-band Total phase (in degrees) | I357: 82JUN21X_ | J357: 11OCT17XA | K357: 2121 | M357: =VLOOKUP(C357,Lcode_mapping!D:D,1,FALSE) -> TOTPHA_S
A358: 150 | B358: 2 | C358: REF FR_S | D358: 1 | E358: 1 | F358: 1 | G358: R | H358: Fr to w.phase is referred S-band | I358: 82JUN21X_ | J358: 11OCT17XA | K358: 2121 | M358: =VLOOKUP(C358,Lcode_mapping!D:D,1,FALSE) -> REF FR_S
A359: 151 | B359: 2 | C359: SNR_S | D359: 1 | E359: 1 | F359: 1 | G359: R | H359: Signal to noise ratio for S-band | I359: 82JUN21X_ | J359: 11OCT17XA | K359: 2121 | M359: =VLOOKUP(C359,Lcode_mapping!D:D,1,FALSE) -> SNR_S
...

Sheet Called from SDBH
A1: CALL GET_STRING( | B1: CORPLACE | C1: CORRELATOR_NAME | E1: =VLOOKUP(B1,#REF!,1,FALSE) -> #REF!
A2: CALL GET_STRING( | B2: CORRTYPE | C2: STR | E2: =VLOOKUP(B2,#REF!,1,FALSE) -> #REF!
A3: CALL GET_STRING( | B3: CROOTFIL | C3: FRINGE_ROOT_FINAM | E3: =VLOOKUP(B3,#REF!,1,FALSE) -> #REF!
A4: CALL GET_STRING( | B4: EOPSCALE | C4: EOP_TS_CALC | E4: =VLOOKUP(B4,#REF!,1,FALSE) -> #REF!
A5: CALL GET_STRING( | B5: ERROR BL | C5: NAMES4ERRORS_HOLD | E5: =VLOOKUP(B5,#REF!,1,FALSE) -> #REF!
A6: CALL GET_STRING( | B6: EXPCODE | C6: STR | E6: =VLOOKUP(B6,#REF!,1,FALSE) -> #REF!
A7: CALL GET_STRING( | B7: EXPDESC | C7: STR | E7: =VLOOKUP(B7,#REF!,1,FALSE) -> #REF!
A8: CALL GET_STRING( | B8: FOURFFIL | C8: FRINGE_X_FINAM | E8: =VLOOKUP(B8,#REF!,1,FALSE) -> #REF!
A9: CALL GET_STRING( | B9: FOURFFXS | C9: FRINGE_S_FINAM | E9: =VLOOKUP(B9,#REF!,1,FALSE) -> #REF!
A10: CALL GET_STRING( | B10: MCALNAMS | C10: MCALNAMS | E10: =VLOOKUP(B10,#REF!,1,FALSE) -> #REF!
A11: CALL GET_STRING( | B11: PI NAME | C11: PI_NAME | E11: =VLOOKUP(B11,#REF!,1,FALSE) -> #REF!
A12: CALL GET_STRING( | B12: RECMODE | C12: REC_MODE | E12: =VLOOKUP(B12,#REF!,1,FALSE) -> #REF!
... A183: CALL GETR(C_EPOCH | B183: CLCKEP | C183: FCLEP | E183: =VLOOKUP(B183,#REF!,1,FALSE) -> #REF!
B184: Lcode Name | C184: Variable

Sheet Pivex_Reject
C2: TOC | D2: ======== | E2: ===== | F2: ===== | G2: === | H2: toc | I2: 1 ====== | J2: ====================================
C3: 1 | D3: ETD DATA | E3: 3 | F3: 1 | G3: 1 | H3: R | I3: 1 | J3: Earth tide module data (la.,h,l) | K3: Delete
C4: 1 | D4: PRE DATA | E4: 1 | F4: 1 | G4: 1 | H4: R | I4: 1 | J4: Precession constant (asec/cent). | K4: Delete
C5: 1 | D5: REL DATA | E5: 1 | F5: 1 | G5: 1 | H5: R | I5: 1 | J5: Relativity mod data (gamma). | K5: Delete
C6: 1 | D6: PI | E6: 1 | F6: 1 | G6: 1 | H6: R | I6: 1 | J6: Pi - to 17 digits accuracy. | K6: Delete
C7: 1 | D7: HALF PI | E7: 1 | F7: 1 | G7: 1 | H7: R | I7: 1 | J7: Half pi - to 17 digits accuracy. | K7: Delete
C8: 1 | D8: RAD/DEG | E8: 1 | F8: 1 | G8: 1 | H8: R | I8: 1 | J8: Number of radians per degree. | K8: Delete
C9: 1 | D9: VLIGHT | E9: 1 | F9: 1 | G9: 1 | H9: R | I9: 1 | J9: The speed of light (m/sec). | K9: Delete
C10: 1 | D10: GAUSS | E10: 1 | F10: 1 | G10: 1 | H10: R | I10: 1 | J10: Gauss's constant (rad). | K10: Delete
C11: 1 | D11: ACCELGRV | E11: 1 | F11: 1 | G11: 1 | H11: R | I11: 1 | J11: Accel grav at erth surface m/s^2 | K11: Delete
C12: 1 | D12: GMSUN | E12: 1 | F12: 1 | G12: 1 | H12: R | I12: 1 | J12: GM of the Sun (m^3/sec^2). | K12: Delete
C13: 1 | D13: GMEARTH | E13: 1 | F13: 1 | G13: 1 | H13: R | I13: 1 | J13: GM of the Earth (m^3/sec^2). | K13: Delete
C14: 1 | D14: GMMOON | E14: 1 | F14: 1 | G14: 1 | H14: R | I14: 1 | J14: GM of the Moon (m^3/sec^2). | K14: Delete
... C209: 1 | D209: HISTRY^C | E209: 40 | F209: 1 | G209: 1 | H209: A | I209: 1 | J209: HISTORY | K209: Delete
D211: ======== | E211: ===== | F211: ===== | G211: === | H211: ==== | I211: == toc 2 | J211: ====================================== | K211: R
C212: 2 | D212: NDRYPART | E212: 2 | F212: 2 | G212: 1 | H212: R | I212: 2 | J212: Nhmf2 dry partial deriv. def. | K212: Delete
C213: 2 | D213: NWETPART | E213: 2 | F213: 2 | G213: 1 | H213: R | I213: 2 | J213: Whmf2 wet partial deriv. def. | K213: Delete
C214: 2 | D214: NDRYCONT | E214: 2 | F214: 2 | G214: 1 | H214: R | I214: 2 | J214: Nhmf (dry) atm. contribution | K214: Delete
C215: 2 | D215: NWETCONT | E215: 2 | F215: 2 | G215: 1 | H215: R | I215: 2 | J215: Whmf (wet) atm. contribution | K215: Delete
